<robot xmlns:xacro="http://www.ros.org/wiki/xacro" name="rover_miti">

    <!-- Robot Parameters -->
    <xacro:property name="wheel_z_offset" value="0.020" />
    <xacro:property name="wheel_x_offset" value="0.1415" />
    <xacro:property name="wheel_y_offset" value="0.18" />
    <xacro:property name="wheel_mass" value="4.53592" />
    <xacro:property name="chassis_mass" value="4.53592" />

    <material name="black">
        <color rgba="0 0 0 1"/>
    </material>

    <!-- Part Includes - Payload, Sensors, Etc.. -->
    <!-- Comment or Uncomment any of these to add them to the dev payload -->
    <!-- You can always link them elsewhere if you wish by editing accessories/<sensor>.urdf -->
    <xacro:property name="payload_z_offset" value="0.156" />
    <xacro:include filename="$(find roverrobotics_description)/urdf/accessories/rover_dev_payload.urdf" />
    <!-- <xacro:include filename="$(find roverrobotics_description)/urdf/accessories/rplidar_s2.urdf" /> -->
    <xacro:include filename="$(find roverrobotics_description)/urdf/accessories/imu.urdf" />

    <xacro:include filename="$(find roverrobotics_description)/urdf/accessories/OS1-64.urdf.xacro" />
    <xacro:OS1-64 parent="payload_link">
        <origin xyz="-0.12 0 0.292" rpy="0 0 1.572" />
    </xacro:OS1-64>


    <link name="gps">
        <visual>
        <geometry>
            <cylinder length="0.083" radius="0.08"/>
        </geometry>
        <material name="black"/>
        </visual>
    </link>

    <joint name="gps_to_payload" type="fixed">
        <parent link="payload_link"/>
        <child link="gps"/>
        <origin xyz="0.135 0 0.09"/>
    </joint>

    <gazebo reference="gps">
        <sensor name="navsat" type="navsat">
          <always_on>1</always_on>
          <update_rate>10</update_rate>
          <topic>/gps/filtered</topic>
          <ignition_frame_id>gps</ignition_frame_id>
        </sensor>
    </gazebo>

    <spherical_coordinates>
        <surface_model>EARTH_WGS84</surface_model>
        <world_frame_orientation>ENU</world_frame_orientation>
        <latitude_deg>44.96944424782721</latitude_deg>
        <longitude_deg>-93.51742744445802</longitude_deg>
        <elevation>0</elevation>
        <heading_deg>0</heading_deg>
    </spherical_coordinates>

    <gazebo>
        <spherical_coordinates>
            <surface_model>EARTH_WGS84</surface_model>
            <world_frame_orientation>ENU</world_frame_orientation>
            <latitude_deg>44.96944424782721</latitude_deg>
            <longitude_deg>-93.51742744445802</longitude_deg>
            <elevation>0</elevation>
            <heading_deg>0</heading_deg>
        </spherical_coordinates>
        <plugin filename="libignition-gazebo-navsat-system" name="ignition::gazebo::systems::NavSat"/>
    </gazebo>

    <link name="80_20">
    <!-- back -->
        <visual>
        <geometry>
            <box size="0.025 0.025 0.24"/>
        </geometry>
        <material name="black"/>
        <origin xyz="-0.05 0.125 0"/>
        </visual>
        
        <visual>
        <geometry>
            <box size="0.025 0.025 0.24"/>
        </geometry>
        <material name="black"/>
        <origin xyz="-0.05 -0.125 0"/>
        </visual>

        <visual>
        <geometry>
            <box size="0.025 0.025 0.24"/>
        </geometry>
        <material name="black"/>
        <origin xyz="-0.05 0 0.1078" rpy="1.572 0 0"/>
        </visual>
    <!-- front -->
        <visual>
        <geometry>
            <box size="0.025 0.025 0.24"/>
        </geometry>
        <material name="black"/>
        <origin xyz="0.05 0.125 0"/>
        </visual>
        
        <visual>
        <geometry>
            <box size="0.025 0.025 0.24"/>
        </geometry>
        <material name="black"/>
        <origin xyz="0.05 -0.125 0"/>
        </visual>

        <visual>
        <geometry>
            <box size="0.025 0.025 0.24"/>
        </geometry>
        <material name="black"/>
        <origin xyz="0.05 0 0.1078" rpy="1.572 0 0"/>
        </visual>
    </link>

    <joint name="payload_to_ouster" type="fixed">
        <parent link="payload_link"/>
        <child link="80_20"/>
        <origin xyz="-0.12 0 0.17"/>
    </joint>

    <!-- Robot Definition -->
    <link name="base_link" />
    <link name="chassis_link">
        <visual>
            <origin xyz="0 0 0" rpy="1.57 -0 3.1415" />
            <geometry>
                <mesh filename="file://$(find roverrobotics_description)/meshes/miti_chassis.dae"/>
            </geometry>
        </visual>

        <collision>
            <origin xyz="0 0 0" rpy="1.57 -0 3.1415" />
            <geometry>
                <mesh filename="file://$(find roverrobotics_description)/meshes/miti_chassis.dae"/>
            </geometry>
        </collision>

        <inertial>
            <origin xyz="0 0 0.056" rpy="0 0 0"/>
            <mass value="${chassis_mass}" />
            <inertia ixx="0.028064" ixy="0.0"  ixz="0.0" iyy="0.08226" iyz="0.0" izz="0.10258" />
        </inertial>
    </link>

    <joint name="base_to_chassis" type="fixed">
        <parent link="base_link"/>
        <child link="chassis_link"/>
        <origin xyz="0 0 0.104"/>
    </joint>

    <link name="fl_wheel_link">
        <visual>
            <origin xyz="0 0 0" rpy="1.57 3.1415 0" />
            <geometry>
                <mesh filename="file://$(find roverrobotics_description)/meshes/hub_10in.dae"/>
            </geometry>
        </visual>

        <collision>
            <origin xyz="0 0 0" rpy="1.57 3.1415 0" />
            <geometry>
                <mesh filename="file://$(find roverrobotics_description)/meshes/hub_10in.dae"/>
            </geometry>
        </collision>

        <inertial>
            <origin xyz="0 0 0" rpy="0 0 0" />
            <mass value="${wheel_mass}" />
            <inertia ixx="0.01937" ixy="0.0"  ixz="0.0" iyy="0.03629" iyz="0.0" izz="0.01937" />
        </inertial>
        <mu>5.0</mu>
    </link>
    <joint name="fl_wheel_to_chassis" type="continuous">
        <parent link="chassis_link"/>
        <child link="fl_wheel_link"/>
        <axis xyz="0 1 0"/>
        <origin xyz="${wheel_x_offset} ${wheel_y_offset} ${wheel_z_offset}"/>
    </joint>

    <link name="fr_wheel_link">
        <visual>
            <origin xyz="0 0 0" rpy="1.57 3.1415 3.1415" />
            <geometry>
                <mesh filename="file://$(find roverrobotics_description)/meshes/hub_10in.dae"/>
            </geometry>
        </visual>

        <collision>
            <origin xyz="0 0 0" rpy="1.57 3.1415 3.1415" />
            <geometry>
                <mesh filename="file://$(find roverrobotics_description)/meshes/hub_10in.dae"/>
            </geometry>
        </collision>

        <inertial>
            <origin xyz="0 0 0" rpy="0 0 0" />
            <mass value="${wheel_mass}" />
            <inertia ixx="0.01937" ixy="0.0"  ixz="0.0" iyy="0.03629" iyz="0.0" izz="0.01937" />
        </inertial>
        <mu>5.0</mu>
    </link>
    <joint name="fr_wheel_to_chassis" type="continuous">
        <parent link="chassis_link"/>
        <child link="fr_wheel_link"/>
        <axis xyz="0 1 0"/>
        <origin xyz="${wheel_x_offset} ${-wheel_y_offset} ${wheel_z_offset}"/>
    </joint>

    <link name="rl_wheel_link">
        <visual>
            <origin xyz="0 0 0" rpy="1.57 3.1415 0" />
            <geometry>
                <mesh filename="file://$(find roverrobotics_description)/meshes/hub_10in.dae"/>
            </geometry>
        </visual>

        <collision>
            <origin xyz="0 0 0" rpy="1.57 3.1415 0" />
            <geometry>
                <mesh filename="file://$(find roverrobotics_description)/meshes/hub_10in.dae"/>
            </geometry>
        </collision>

        <inertial>
            <origin xyz="0 0 0" rpy="0 0 0" />
            <mass value="${wheel_mass}" />
            <inertia ixx="0.01937" ixy="0.0"  ixz="0.0" iyy="0.03629" iyz="0.0" izz="0.01937" />
        </inertial>
        <mu>5.0</mu>
    </link>
    <joint name="rl_wheel_to_chassis" type="continuous">
        <parent link="chassis_link"/>
        <child link="rl_wheel_link"/>
        <axis xyz="0 1 0"/>
        <origin xyz="${-wheel_x_offset} ${wheel_y_offset} ${wheel_z_offset}"/>
    </joint>

    <link name="rr_wheel_link">
        <visual>
            <origin xyz="0 0 0" rpy="1.57 3.1415 3.1415" />
            <geometry>
                <mesh filename="file://$(find roverrobotics_description)/meshes/hub_10in.dae"/>
            </geometry>
        </visual>

        <collision>
            <origin xyz="0 0 0" rpy="1.57 3.1415 3.1415" />
            <geometry>
                <mesh filename="file://$(find roverrobotics_description)/meshes/hub_10in.dae"/>
            </geometry>
        </collision>

        <inertial>
            <origin xyz="0 0 0" rpy="0 0 0" />
            <mass value="${wheel_mass}" />
            <inertia ixx="0.01937" ixy="0.0"  ixz="0.0" iyy="0.03629" iyz="0.0" izz="0.01937" />
        </inertial>
        <mu>5.0</mu>
    </link>
    <joint name="rr_wheel_to_chassis" type="continuous">
        <parent link="chassis_link"/>
        <child link="rr_wheel_link"/>
        <axis xyz="0 1 0"/>
        <origin xyz="${-wheel_x_offset} ${-wheel_y_offset} ${wheel_z_offset}"/>
    </joint>
    

    <!-- Gazebo Plugins -->
    <gazebo>
        <plugin name="ignition::gazebo::systems::DiffDrive" filename="ignition-gazebo-diff-drive-system"> 
            <num_wheel_pairs>2</num_wheel_pairs>
            <!-- Wheel Information -->
            <left_joint>rl_wheel_to_chassis</left_joint>
            <left_joint>fl_wheel_to_chassis</left_joint>
            <right_joint>rr_wheel_to_chassis</right_joint>
            <right_joint>fr_wheel_to_chassis</right_joint>
            <wheel_separation>0.35</wheel_separation>
            <wheel_radius>0.122</wheel_radius>

            <!-- Limits -->
            <max_linear_acceleration>5</max_linear_acceleration>
            <min_linear_acceleration>-5</min_linear_acceleration>
            <max_angular_acceleration>4</max_angular_acceleration>
            <min_angular_acceleration>-4</min_angular_acceleration>

            
            <!-- Output -->
            <frame_id>odom</frame_id>
            <child_frame_id>base_link</child_frame_id>

            <!-- Topics -->
            <topic>/cmd_vel</topic>
            <odom_topic>/odometry/wheels</odom_topic>
            <tf_topic>/tf_gazebo</tf_topic>

        </plugin>

        <plugin filename="ignition-gazebo-joint-state-publisher-system" name="ignition::gazebo::systems::JointStatePublisher">
            <topic>/joint_states</topic>
        </plugin>
    </gazebo>

    <gazebo reference="fl_wheel_link">
        <mu1 value="200.0" />
        <mu2 value="200.0" />
        <kp  value="1000000.0" />
        <kd  value="1.0" />
        <minDepth>0.005</minDepth>
    </gazebo>
    <gazebo reference="fr_wheel_link">
        <mu1 value="200.0" />
        <mu2 value="200.0" />
        <kp  value="1000000.0" />
        <kd  value="1.0" />
        <minDepth>0.005</minDepth>
    </gazebo>
    <gazebo reference="rl_wheel_link">
        <mu1 value="200.0" />
        <mu2 value="200.0" />
        <kp  value="1000000.0" />
        <kd  value="1.0" />
        <minDepth>0.005</minDepth>
    </gazebo>
    <gazebo reference="rr_wheel_link">
        <mu1 value="200.0" />
        <mu2 value="200.0" />
        <kp  value="1000000.0" />
        <kd  value="1.0" />
        <minDepth>0.005</minDepth>
    </gazebo>

</robot>
